Workbook

Sheet Summary
A1: Inditex (BME: ITX) - Equity Research Model
A2: Model date 30-Jul-26. Fiscal years ended 31 January of year shown (model FY2026 = company FY2025).
A4: MARKET DATA
A5: Current share price (€) | B5: =Assumptions!F41 -> 57.28
A6: Shares outstanding (m) | B6: =Assumptions!F40 -> 3116.1
A7: Market cap (€m) | B7: =Assumptions!F57 -> 178490.21
A8: Net cash after lease liabilities (€m) | B8: =Assumptions!F43-Assumptions!F42 -> 5025
A10: VALUATION SUMMARY - IMPLIED SHARE PRICE (€) | C10: vs current | D10: Range (each block = €2)
A11: DCF - bear case (beta 1.10) | B11: =Scenarios!E8 -> 29.204523 | C11: =(B11-$B$16)/$B$16 -> -0.4901445 | D11: =REPT("█",ROUND(B11/2,0)) -> ███████████████
A12: DCF - base case (beta 0.90) | B12: =DCF!B35 -> 34.364677 | C12: =(B12-$B$16)/$B$16 -> -0.400058 | D12: =REPT("█",ROUND(B12/2,0)) -> █████████████████
A13: DCF - bull case (beta 0.65) | B13: =Scenarios!E6 -> 44.457416 | C13: =(B13-$B$16)/$B$16 -> -0.22385797 | D13: =REPT("█",ROUND(B13/2,0)) -> ██████████████████████
A14: Comps - EV/EBITDA (peer median) | B14: =Comps!B36 -> 31.642133 | C14: =(B14-$B$16)/$B$16 -> -0.44758846 | D14: =REPT("█",ROUND(B14/2,0)) -> ████████████████
A15: Comps - EV/Sales (core peers) | B15: =Comps!B37 -> 36.921036 | C15: =(B15-$B$16)/$B$16 -> -0.35542884 | D15: =REPT("█",ROUND(B15/2,0)) -> ██████████████████
A16: Current share price | B16: =Assumptions!F41 -> 57.28 | D16: =REPT("█",ROUND(B16/2,0)) -> █████████████████████████████
A18: MODEL VIEW: SELL
A19: Every methodology lands well below the market. Base-case DCF implies ~40% downside; the price only reconciles with a beta of ~0.46 vs 0.90 measured (Scenarios tab). Terminal assumptions already hold margins at all-time highs.
A21: KEY ASSUMPTIONS
A22: Revenue growth FY2027E-FY2031E (fade) | B22: =Assumptions!G17 -> 0.06 | C22: =Assumptions!K17 -> 0.04
A23: EBIT margin (held near record) | B23: =Assumptions!G18 -> 0.202 | C23: =Assumptions!K18 -> 0.203
A24: WACC (base) | B24: =Assumptions!F45 -> 0.080737121
A25: Terminal growth | B25: =Assumptions!F44 -> 0.025
A26: Terminal value as % of EV | B26: =DCF!B40 -> 0.77439026
A27: Implied exit EV/EBITDA (lease-adj.) | B27: =DCF!B41 -> 9.1613045 | C27: vs current | D27: =DCF!B42 -> 18.48324
A29: HOW TO READ THIS MODEL
A30: Blue = hardcoded input (source noted alongside)
A31: Black = formula (same sheet)
A32: Green = link to another sheet
A33: Tabs: Assumptions (drivers, WACC) > DCF (valuation, sensitivities) > Comps > Scenarios.

Sheet Assumptions
A1: Inditex (BME: ITX) - Model Assumptions
A2: Fiscal years ended 31 January of year shown (model "FY2026" = company-reported "FY2025", ended 31-Jan-2026). All figures €m unless stated.
B3: FY2022 | C3: FY2023 | D3: FY2024 | E3: FY2025 | F3: FY2026 | G3: FY2027E | H3: FY2028E | I3: FY2029E | J3: FY2030E | K3: FY2031E
A4: Revenue (€m) | B4: 27716 | C4: 32569 | D4: 35947 | E4: 38632 | F4: 39864 | G4: =F4*(1+G17) -> 42255.84 | H4: =G4*(1+H17) -> 44579.911 | I4: =H4*(1+I17) -> 46808.907 | J4: =I4*(1+J17) -> 48915.308 | K4: =J4*(1+K17) -> 50871.92
A5: Revenue growth (%) | B5: n/a | C5: =(C4-B4)/B4 -> 0.17509742 | D5: =(D4-C4)/C4 -> 0.10371826 | E5: =(E4-D4)/D4 -> 0.074693298 | F5: =(F4-E4)/E4 -> 0.031890661 | G5: =(G4-F4)/F4 -> 0.06 | H5: =(H4-G4)/G4 -> 0.055 | I5: =(I4-H4)/H4 -> 0.05 | J5: =(J4-I4)/I4 -> 0.045 | K5: =(K4-J4)/J4 -> 0.04
A6: EBITDA, lease-adjusted (€m) | B6: 5558 | C6: 6779 | D6: 8148 | E6: 8878 | F6: 9385 | G6: =G8+G12 -> 10120.274 | H6: =H8+H12 -> 10676.889 | I6: =I8+I12 -> 11257.542 | J6: =J8+J12 -> 11764.131 | K6: =K8+K12 -> 12234.697
A7: EBITDA margin, lease-adj. (%) | B7: =B6/B4 -> 0.20053399 | C7: =C6/C4 -> 0.20814271 | D7: =D6/D4 -> 0.22666704 | E7: =E6/E4 -> 0.22980948 | F7: =F6/F4 -> 0.23542545 | G7: =G6/G4 -> 0.2395 | H7: =H6/H4 -> 0.2395 | I7: =I6/I4 -> 0.2405 | ... K7: =K6/K4 -> 0.2405
A8: EBIT (€m) | B8: 4264 | C8: 5571 | D8: 6856 | E8: 7594 | F8: 8045 | G8: =G4*G18 -> 8535.6797 | H8: =H4*H18 -> 9005.1421 | I8: =I4*I18 -> 9502.2081 | J8: =J4*J18 -> 9929.8074 | K8: =K4*K18 -> 10327
A9: EBIT margin (%) | B9: =B8/B4 -> 0.15384615 | C9: =C8/C4 -> 0.17105223 | D9: =D8/D4 -> 0.19072523 | E9: =E8/E4 -> 0.19657279 | F9: =F8/F4 -> 0.20181116 | G9: =G8/G4 -> 0.202 | H9: =H8/H4 -> 0.202 | I9: =I8/I4 -> 0.203 | ... K9: =K8/K4 -> 0.203
A10: NOPAT / proxy net income (€m) | B10: 3243 | C10: 4130 | D10: 5381 | E10: 5866 | F10: 6220 | G10: =G8*(1-G19) -> 6615.1518 | H10: =H8*(1-H19) -> 6978.9851 | I10: =I8*(1-I19) -> 7316.7002 | J10: =J8*(1-J19) -> 7645.9517 | K10: =K8*(1-K19) -> 7951.7898
A11: NOPAT / proxy net margin (%) | B11: =B10/B4 -> 0.11700823 | C11: =C10/C4 -> 0.1268077 | D11: =D10/D4 -> 0.1496926 | E11: =E10/E4 -> 0.15184303 | F11: =F10/F4 -> 0.1560305 | G11: =G10/G4 -> 0.15655 | H11: =H10/H4 -> 0.15655 | I11: =I10/I4 -> 0.15631 | ... K11: =K10/K4 -> 0.15631
A12: D&A excl. lease depreciation (€m) | B12: =B6-B8 -> 1294 | C12: =C6-C8 -> 1208 | D12: =D6-D8 -> 1292 | E12: =E6-E8 -> 1284 | F12: =F6-F8 -> 1340 | G12: =G4*G20 -> 1584.594 | H12: =H4*H20 -> 1671.7467 | I12: =I4*I20 -> 1755.334 | J12: =J4*J20 -> 1834.324 | K12: =K4*K20 -> 1907.697
A13: D&A (excl. lease dep.) as % of revenue | B13: =B12/B4 -> 0.046687834 | C13: =C12/C4 -> 0.037090485 | D13: =D12/D4 -> 0.035941803 | E13: =E12/E4 -> 0.033236695 | F13: =F12/F4 -> 0.033614289 | G13: =G12/G4 -> 0.0375 | H13: =H12/H4 -> 0.0375 | I13: =I12/I4 -> 0.0375 | ... K13: =K12/K4 -> 0.0375
A14: Note: EBITDA shown is lease-adjusted (post-IFRS 16 EBIT + non-lease D&A). Reported FY2026 EBITDA was €11,315m (EBIT €8,045m + total D&A €3,270m per CFS); the €1,930m difference is lease depreciation. See Comps tab for the reported-basis figure used in multiples.
A16: PROJECTION ASSUMPTIONS
A17: Revenue growth assumption (%) | G17: 0.06 | H17: 0.055 | I17: 0.05 | J17: 0.045 | K17: 0.04
A18: EBIT margin assumption (%) | G18: 0.202 | H18: 0.202 | I18: 0.203 | J18: 0.203 | K18: 0.203
A19: Tax rate (%) | G19: 0.225 | H19: 0.225 | I19: 0.23 | J19: 0.23 | K19: 0.23
A20: D&A (excl. lease dep.) as % of revenue | G20: 0.0375 | H20: 0.0375 | I20: 0.0375 | J20: 0.0375 | K20: 0.0375
A21: Revenue growth cross-check (illustrative split - replace with company disclosure):
A22: of which net space contribution (%) | G22: 0.02 | H22: 0.02 | I22: 0.02 | J22: 0.015 | K22: 0.015 | L22: Illustrative: FY2026 saw 190 openings / 293 absorptions on 5,460 stores; verify net space growth from company disclosures
A23: of which LFL / price-mix (%) | G23: =G17-G22 -> 0.04 | H23: =H17-H22 -> 0.035 | I23: =I17-I22 -> 0.03 | J23: =J17-J22 -> 0.03 | K23: =K17-K22 -> 0.025
A26: FREE CASH FLOW INPUTS
A27: Capex (€m) | E27: 2672 | F27: 2712
A28: Capex as % of revenue | E28: =E27/E4 -> 0.069165459 | F28: =F27/F4 -> 0.068031306
A29: Working capital change per CFS (€m; negative = cash outflow) | E29: -198 | F29: -803 | L29: Source: FY2025 CFS - changes in working capital (803) FY2025, (198) FY2024 (company fiscal labels)
A30: WC change as % of revenue | E30: =E29/E4 -> -0.0051252847 | F30: =F29/F4 -> -0.020143488
A31: Capex as % of revenue assumption | G31: 0.069 | H31: 0.069 | I31: 0.069 | J31: 0.069 | K31: 0.069 | L31: Above company guidance of €2.3bn / ~5.5% of revenye for FY2027; maintained at historical rate as conservative assumption
A32: WC cash impact as % of revenue assumption (negative = outflow) | G32: -0.005 | H32: -0.005 | I32: -0.005 | J32: -0.005 | K32: -0.005
A34: INDICATIVE HISTORICAL UNLEVERED FCF
A35: Unlevered FCF (€m) | E35: =E8*(1-$F$54)+E12-E27+E29 -> 4261.38 | F35: =F8*(1-$F$54)+F12-F27+F29 -> 4019.65
A36: FCF margin (%) | E36: =E35/E4 -> 0.110307 | F36: =F35/F4 -> 0.10083409
A37: Indicative: EBIT x (1 - 23%) + non-lease D&A - capex + WC change per CFS. Same construction as forecast FCF for comparability.
A39: VALUATION INPUTS
A40: Current shares outstanding (m) | F40: 3116.1
A41: Current share price (€) | F41: 57.28 | G41: Yahoo Finance, 30-Jul-26
A42: Total debt = IFRS 16 lease liabilities (€m) | F42: 5935 | G42: FY2026 balance sheet: current lease liability €1,539m + non-current. Inditex carries no material financial debt.
A43: Cash, equivalents & ST investments (€m) | F43: 10960 | G43: Company-stated net cash position €11.0bn, FY2025 results release
A44: Terminal growth rate (%) | F44: 0.025
A45: WACC (%) | F45: =F62 -> 0.080737121
...

Sheet DCF
A1: Inditex (BME: ITX) - DCF Valuation
A2: Mid-year discounting convention. All figures €m unless stated.
B3: FY2027E | C3: FY2028E | D3: FY2029E | E3: FY2030E | F3: FY2031E
A5: FREE CASH FLOW
A6: Revenue (€m) | B6: =Assumptions!G4 -> 42255.84 | C6: =Assumptions!H4 -> 44579.911 | D6: =Assumptions!I4 -> 46808.907 | E6: =Assumptions!J4 -> 48915.308 | F6: =Assumptions!K4 -> 50871.92
A7: EBIT (€m) | B7: =Assumptions!G8 -> 8535.6797 | C7: =Assumptions!H8 -> 9005.1421 | D7: =Assumptions!I8 -> 9502.2081 | E7: =Assumptions!J8 -> 9929.8074 | F7: =Assumptions!K8 -> 10327
A8: Tax rate (%) | B8: =Assumptions!G19 -> 0.225 | C8: =Assumptions!H19 -> 0.225 | D8: =Assumptions!I19 -> 0.23 | E8: =Assumptions!J19 -> 0.23 | F8: =Assumptions!K19 -> 0.23
A9: NOPAT (€m) | B9: =B7*(1-B8) -> 6615.1518 | C9: =C7*(1-C8) -> 6978.9851 | D9: =D7*(1-D8) -> 7316.7002 | E9: =E7*(1-E8) -> 7645.9517 | F9: =F7*(1-F8) -> 7951.7898
A10: Add: D&A excl. lease depreciation (€m) | B10: =Assumptions!G12 -> 1584.594 | C10: =Assumptions!H12 -> 1671.7467 | D10: =Assumptions!I12 -> 1755.334 | E10: =Assumptions!J12 -> 1834.324 | F10: =Assumptions!K12 -> 1907.697
A11: Less: Capex (€m) | B11: =-B6*Assumptions!G31 -> -2915.653 | C11: =-C6*Assumptions!H31 -> -3076.0139 | D11: =-D6*Assumptions!I31 -> -3229.8146 | E11: =-E6*Assumptions!J31 -> -3375.1562 | F11: =-F6*Assumptions!K31 -> -3510.1625
A12: Working capital cash impact (€m; negative = outflow) | B12: =B6*Assumptions!G32 -> -211.2792 | C12: =C6*Assumptions!H32 -> -222.89956 | D12: =D6*Assumptions!I32 -> -234.04453 | E12: =E6*Assumptions!J32 -> -244.57654 | F12: =F6*Assumptions!K32 -> -254.3596
A13: Free Cash Flow (€m) | B13: =SUM(B9:B12) -> 5072.8136 | C13: =SUM(C9:C12) -> 5351.8183 | D13: =SUM(D9:D12) -> 5608.1751 | E13: =SUM(E9:E12) -> 5860.543 | F13: =SUM(F9:F12) -> 6094.9647
A15: DISCOUNTING
A16: WACC (%) | B16: =Assumptions!F45 -> 0.080737121
A17: Discount period (mid-year) | B17: 0.5 | C17: 1.5 | D17: 2.5 | E17: 3.5 | F17: 4.5
A18: Discount factor | B18: =1/((1+$B$16)^B17) -> 0.96192224 | C18: =1/((1+$B$16)^C17) -> 0.89006126 | D18: =1/((1+$B$16)^D17) -> 0.82356869 | E18: =1/((1+$B$16)^E17) -> 0.76204349 | F18: =1/((1+$B$16)^F17) -> 0.70511457
A19: PV of FCF (€m) | B19: =B13*B18 -> 4879.6522 | C19: =C13*C18 -> 4763.4462 | D19: =D13*D18 -> 4618.7174 | E19: =E13*E18 -> 4465.9887 | F19: =F13*F18 -> 4297.6484
A21: TERMINAL VALUE
A22: Terminal growth rate (%) | F22: =Assumptions!F44 -> 0.025
A23: Terminal year FCF (€m) | F23: =F13 -> 6094.9647
A24: Terminal value (€m) | F24: =(F23*(1+F22))/($B$16-F22) -> 112085.78
A25: PV of terminal value (€m) | F25: =F24*F18 -> 79033.319
A27: VALUATION
A28: Sum of PV of FCFs (€m) | B28: =SUM(B19:F19) -> 23025.453
A29: PV of terminal value (€m) | B29: =F25 -> 79033.319
A30: Enterprise value (€m) | B30: =B28+B29 -> 102058.77
A31: Less: lease liabilities (€m) | B31: =-Assumptions!F42 -> -5935
A32: Add: cash & ST investments (€m) | B32: =Assumptions!F43 -> 10960
A33: Equity value (€m) | B33: =SUM(B30:B32) -> 107083.77
A34: Shares outstanding (m) | B34: =Assumptions!F40 -> 3116.1
A35: Implied share price (€) | B35: =B33/B34 -> 34.364677
A36: Current share price (€) | B36: =Assumptions!F41 -> 57.28
A37: Implied upside / (downside) (%) | B37: =(B35-B36)/B36 -> -0.400058
A39: CROSS-CHECKS
A40: Terminal value as % of EV | B40: =B29/B30 -> 0.77439026
A41: Implied exit EV/EBITDA (lease-adj., x) | B41: =F24/Assumptions!K6 -> 9.1613045 | C41: Exit multiple well below current: the Sell case in one number
A42: Current EV/EBITDA (lease-adj., x) | B42: =(Assumptions!F57+Assumptions!F42-Assumptions!F43)/Assumptions!F6 -> 18.48324
A43: Terminal EBITDA margin (lease-adj., %) | B43: =Assumptions!K7 -> 0.2405 | C43: vs 23.5% FY2026A - assumes margins hold at all-time high in perpetuity
A44: FCF margin FY2031E (%) | B44: =F13/F6 -> 0.11981
A46: Lease (IFRS 16) framework: EBIT is post-IFRS 16 as reported; the D&A add-back excludes lease depreciation and capex excludes right-of-use additions (approximately offsetting); lease interest is excluded from unlevered FCF; the full lease liability (€5,935m) is deducted as debt in the bridge. Internally consistent treatment.
...

Sheet Comps
A1: Inditex (BME: ITX) - Trading Comparables
A2: Peer multiples on reported (post-IFRS 16) financials. Prices as of 30-Jul-26.
A4: FX ASSUMPTIONS
A5: Date of rates | B5: 46233
B6: GBP/EUR | C6: SEK/EUR | D6: JPY/EUR | E6: USD/EUR
A7: Rate (1 foreign unit = x EUR) | B7: 1.17 | C7: 0.091 | D7: 0.054 | E7: 0.92
A8: Note: GBp tickers (Next, M&S, ABF) report in pence - divide market cap by 100 before applying GBP/EUR. Multiples are currency-neutral and need no conversion.
A10: COMPARABLE COMPANIES
A11: Company | B11: Ticker | C11: Market cap (€bn) | D11: EV (€bn) | E11: EV/Sales (x) | F11: EV/EBITDA (x) | G11: P/E (x) | H11: Notes
A12: H&M (Hennes & Mauritz) | B12: HMB:SS | C12: 25.34 | D12: 28.76 | E12: 1.43 | F12: 8.06 | G12: 22.68 | H12: Closest business-model twin - identical model, radically worse execution. The EV/EBITDA gap (8.1x vs ~15x) quantifies what the market pays for operational excellence within the same format.
A13: Fast Retailing | B13: 9983:JP | C13: 133.2 | D13: 124.9 | E13: 6.31 | F13: 24.28 | G13: 51.6 | H13: Only peer at comparable scale and quality. Trades richer than Inditex on every metric - the single most important check on the "priced for permanence" thesis. If the market pays 51x for Uniqlo, ~29x for Inditex is internally consistent.
A14: Next plc | B14: NXT:LN | C14: 20.4 | D14: 22.3 | E14: 2.76 | F14: 11.72 | G14: 20.36 | H14: Sharpest bear-case exhibit. Comparable execution quality and capital discipline at well under half the EV/EBITDA multiple. The "why pay up?" question made concrete - the premium must be earned by growth and geography, not quality alone.
A15: Zalando | B15: ZAL:GR | C15: 7.39 | D15: 7.47 | E15: 0.58 | F15: 9.98 | G15: 27.86 | H15: Pure-play online proxy. EV/Sales of 0.58x vs Inditex's ~4.4x shows how differently the market values online-only revenue versus integrated retail. Digital channel growing slower than group at Inditex makes this increasingly relevant.
A16: Associated British Foods | B16: ABF:LN | C16: 17.2 | D16: 20.7 | E16: 0.91 | F16: 6.75 | G16: 15.76 | H16: Conglomerate - group multiples contaminated by sugar, grocery and ingredients divisions; excluded from core EV/Sales median. Deep-discount no-ecommerce contrast - the most direct casualty of Shein/Temu pressure that Zara's positioning largely avoids.
A17: Marks & Spencer | B17: MKS:LN | C17: 9.7 | D17: 12.6 | E17: 0.62 | F17: 8.27 | G17: 15.06 | H17: Legacy retailer turnaround. Clothing competes with Massimo Dutti in the UK. Forward P/E used - trailing (33x) distorted by one-off items. EV/EBITDA almost identical to H&M despite a fundamentally different trajectory.
A18: Gap | B18: GAP:US | C18: 6.3 | D18: 8.5 | E18: 0.6 | F18: 8.05 | G18: 7.6 | H18: US/Americas reference - the geography where Inditex's growth optionality sits (17.8% of revenue, Bershka US entry underway). P/E ~7.6x (trailing, re-verified late-Jul-26) shows how brutally the US prices apparel without pricing power. Sets the floor the Americas expansion must clear.
A20: Peer median (all 7) | E20: =MEDIAN(E12:E18) -> 0.91 | F20: =MEDIAN(F12:F18) -> 8.27 | G20: =MEDIAN(G12:G18) -> 20.36
A21: Peer mean (all 7) | E21: =AVERAGE(E12:E18) -> 1.8871429 | F21: =AVERAGE(F12:F18) -> 11.015714 | G21: =AVERAGE(G12:G18) -> 22.988571
A22: Core peers median (H&M, Fast Retailing, Next) | E22: =MEDIAN(E12:E14) -> 2.76 | F22: =MEDIAN(F12:F14) -> 11.72 | G22: =MEDIAN(G12:G14) -> 22.68
A24: Inditex (on FY2026A model financials) | B24: ITX:SM | C24: =Assumptions!F57/1000 -> 178.49021 | D24: =(Assumptions!F57+Assumptions!F42-Assumptions!F43)/1000 -> 173.46521 | E24: =D24*1000/Assumptions!F4 -> 4.351425 | F24: =D24*1000/B28 -> 15.330553 | G24: =C24*1000/Assumptions!F10 -> 28.696175 | H24: Subject company. Multiples computed live from model inputs on FY2026A reported figures (EBITDA on reported post-IFRS 16 basis, row 28) - may differ slightly from screen-quoted trailing multiples.
A26: Premium / (discount) to peer median | E26: =(E24-E20)/E20 -> 3.7817858 | F26: =(F24-F20)/F20 -> 0.85375491 | G26: =(G24-G20)/G20 -> 0.40943885
A28: INDITEX FY2026A REPORTED EBITDA (for multiples) | B28: 11315 | C28: EBIT €8,045m + total D&A €3,270m per FY2025 CFS (post-IFRS 16, consistent with peer multiple basis)
A30: IMPLIED VALUATION FROM PEER MULTIPLES
A31: Implied EV - peer median EV/EBITDA x reported EBITDA (€m) | B31: =F20*B28 -> 93575.05
A32: Implied EV - core-peer median EV/Sales x revenue (€m) | B32: =E22*Assumptions!F4 -> 110024.64
A34: Implied equity value - EV/EBITDA (€m) | B34: =B31-Assumptions!F42+Assumptions!F43 -> 98600.05
A35: Implied equity value - EV/Sales (€m) | B35: =B32-Assumptions!F42+Assumptions!F43 -> 115049.64
A36: Implied share price - EV/EBITDA (€) | B36: =B34/Assumptions!F40 -> 31.642133
A37: Implied share price - EV/Sales, core peers (€) | B37: =B35/Assumptions!F40 -> 36.921036
A38: EV/Sales uses core-peer median only (H&M, Fast Retailing, Next): the full-peer median (0.9x) is set by ABF and M&S, whose conglomerate/food mix makes it meaningless for Inditex. Peer EV/EBITDA is post-IFRS 16, so it is applied to reported EBITDA and lease debt is then deducted in the bridge - consistent basis.
A40: VALUATION SUMMARY
A41: Comps implied - EV/EBITDA, peer median (€) | B41: =B36 -> 31.642133
A42: Comps implied - EV/Sales, core peers (€) | B42: =B37 -> 36.921036
A43: DCF implied - base case (€) | B43: =DCF!B35 -> 34.364677
A44: DCF implied - bull case (€) | B44: =Scenarios!E6 -> 44.457416
A45: DCF implied - bear case (€) | B45: =Scenarios!E8 -> 29.204523
A46: Current share price (€) | B46: =Assumptions!F41 -> 57.28
A48: Downside to base-case DCF (%) | B48: =(B43-B46)/B46 -> -0.400058
A49: Downside to EV/EBITDA comps (%) | B49: =(B41-B46)/B46 -> -0.44758846
A51: Sources: Yahoo Finance, 30-Jul-26. P/E trailing unless stated; M&S forward (trailing distorted by restructuring charges). Gap figures re-verified late-Jul-26 (P/E ~7.6x trailing). ABF multiples reflect group consolidation - Primark not separately disclosed. ASOS, Burberry and LVMH excluded - see investment thesis for rationale.

Sheet Scenarios
A1: Scenario Analysis - Cost of Equity Sensitivity
A2: Live formulas: scenarios recompute from DCF cash flows and WACC inputs. No stale hardcodes.
A5: Scenario | B5: Beta | C5: Cost of equity (%) | D5: WACC (%) | E5: Implied price (€) | F5: Upside / (downside) (%) | G5: Rationale | H5: Check
A6: Bull case | B6: 0.65 | C6: =Assumptions!$F$48+B6*Assumptions!$F$50 -> 0.06875 | D6: =Assumptions!$F$60*C6+Assumptions!$F$61*Assumptions!$F$55 -> 0.067429611 | E6: =(SUMPRODUCT(DCF!$B$13:$F$13,(1+$D6)^-(DCF!$B$17:$F$17))+(DCF!$F$13*(1+Assumptions!$F$44)/($D6-Assumptions!$F$44))*(1+$D6)^-4.5+Assumptions!$F$43-Assumptions!$F$42)/Assumptions!$F$40 -> 44.457416 | F6: =(E6-Assumptions!$F$41)/Assumptions!$F$41 -> -0.22385797 | G6: Low-beta defensive read; near bottom of observed range
A7: Base case | B7: =Assumptions!F49 -> 0.9 | C7: =Assumptions!$F$48+B7*Assumptions!$F$50 -> 0.0825 | D7: =Assumptions!$F$60*C7+Assumptions!$F$61*Assumptions!$F$55 -> 0.080737121 | E7: =(SUMPRODUCT(DCF!$B$13:$F$13,(1+$D7)^-(DCF!$B$17:$F$17))+(DCF!$F$13*(1+Assumptions!$F$44)/($D7-Assumptions!$F$44))*(1+$D7)^-4.5+Assumptions!$F$43-Assumptions!$F$42)/Assumptions!$F$40 -> 34.364677 | F7: =(E7-Assumptions!$F$41)/Assumptions!$F$41 -> -0.400058 | G7: Yahoo Finance 5yr monthly, 30-Jul-26 (see beta note on Assumptions) | H7: =E7-DCF!B35 -> 0 | I7: Base case must equal DCF tab (=0.00)
A8: Bear case | B8: 1.1 | C8: =Assumptions!$F$48+B8*Assumptions!$F$50 -> 0.0935 | D8: =Assumptions!$F$60*C8+Assumptions!$F$61*Assumptions!$F$55 -> 0.091383129 | E8: =(SUMPRODUCT(DCF!$B$13:$F$13,(1+$D8)^-(DCF!$B$17:$F$17))+(DCF!$F$13*(1+Assumptions!$F$44)/($D8-Assumptions!$F$44))*(1+$D8)^-4.5+Assumptions!$F$43-Assumptions!$F$42)/Assumptions!$F$40 -> 29.204523 | F8: =(E8-Assumptions!$F$41)/Assumptions!$F$41 -> -0.4901445 | G8: Discretionary retail; China and US cyclical exposure
A10: Beta implied by current share price (€57.28) | B10: 0.46 | C10: Solved numerically (goal-seek on DCF price = market price), 01-Aug-26; re-solve if model inputs change. Market implies a beta far below any measured estimate - the core of the Sell case: the price only works if you believe Inditex is materially less risky than its own trading history suggests.
